Workbook
Name DPP: 'Резюме (Проекта 1)'!$B$12
Name DPP: #REF!

Sheet TCO (Проект 1)
A1: БЮДЖЕТ ПРОЕКТА U20000XXXX
A3: Единица измерения: | B3: тыс руб.
A5: Статья затрат | B5: 2020 | C5: 2021 | D5: 2022 | E5: 2023 | F5: 2024 | G5: 2025 | H5: 2026 | I5: 2027 | J5: 2028 | K5: 2029 | L5: Итого по статье
A6: Капитальные затраты (CAPEX):
A7: Консалтинг внешний, CAPEX | D7: 1500 | E7: 4500 | L7: =SUM(B7:K7) -> 6000
A8: в т.ч. затраты на сопровождение ИБ, CAPEX** | E8: 500 | L8: =SUM(B8:K8) -> 500
A9: в т.ч. внедрение СЗИ/компонентов сервисов ИБ, CAPEX** | E9: 100 | L9: =SUM(B9:K9) -> 100
A10: Лицензии (право использования), CAPEX | E10: 450 | L10: =SUM(B10:K10) -> 450
A11: Консалтинг (Управление проектами), CAPEX | D11: 250 | E11: 200 | L11: =SUM(B11:K11) -> 450
A12: Консалтинг (Бизнес анализ), CAPEX | L12: =SUM(B12:K12) -> 0
A13: Консалтинг (Расходы на ИБ), CAPEX | L13: =SUM(B13:K13) -> 0
A14: Консалтинг (Архитектура), CAPEX | L14: =SUM(B14:K14) -> 0
A15: Итого капитальные затраты (CAPEX)*: | B15: =SUM(B7,B10:B14) -> 0 | C15: =SUM(C7,C10:C14) -> 0 | D15: =SUM(D7,D10:D14) -> 1750 | E15: =SUM(E7,E10:E14) -> 5150 | F15: =SUM(F7,F10:F14) -> 0 | G15: =SUM(G7,G10:G14) -> 0 | H15: =SUM(H7,H10:H14) -> 0 | I15: =SUM(I7,I10:I14) -> 0 | ... L15: =SUM(L7,L10:L14) -> 6900
A17: Операционные затраты (OPEX):
A18: Консалтинг внешний, OPEX | C18: 600 | L18: =SUM(B18:K18) -> 600
A19: Консалтинг внутренний (Управление проектами), OPEX | C19: 450 | D19: 250 | L19: =SUM(B19:K19) -> 700
A20: Консалтинг внутренний (Расходы на ИБ), OPEX | C20: 40 | L20: =SUM(B20:K20) -> 40
A21: Консалтинг внутренний (Бизнес-анализ), OPEX | C21: 40 | L21: =SUM(B21:K21) -> 40
A22: Консалтинг внутренний (Архитектура), OPEX | C22: 150 | L22: =SUM(B22:K22) -> 150
A23: Затраты на аренду оборудования IaaS, OPEX | L23: =SUM(B23:K23) -> 0
A24: Затраты на сопровождение на этапе эксплуатации, OPEX* | D24: 300 | E24: 300 | F24: 300 | G24: 300 | H24: 300 | I24: 300 | J24: 300 | K24: 300 | L24: =SUM(B24:K24) -> 2400
A25: в т.ч. затраты на сопровождение ИБ (эксплуатация), OPEX** | D25: 100 | E25: 100 | F25: 100 | G25: 100 | H25: 100 | I25: 100 | J25: 100 | K25: 100 | L25: =SUM(B25:K25) -> 800
A26: Итого операционные затраты (OPEX): | B26: =SUM(B18:B24) -> 0 | C26: =SUM(C18:C24) -> 1280 | D26: =SUM(D18:D24) -> 550 | E26: =SUM(E18:E24) -> 300 | F26: =SUM(F18:F24) -> 300 | G26: =SUM(G18:G24) -> 300 | H26: =SUM(H18:H24) -> 300 | I26: =SUM(I18:I24) -> 300 | ... L26: =SUM(L18:L24) -> 3930
A28: Итого по проекту за период (руб.): | C28: =C15+C26 -> 1280 | D28: =D15+D26 -> 2300 | E28: =E15+E26 -> 5450 | F28: =F15+F26 -> 300 | G28: =G15+G26 -> 300 | H28: =H15+H26 -> 300 | I28: =I15+I26 -> 300 | J28: =J15+J26 -> 300 | K28: =K15+K26 -> 300 | L28: =SUM(B28:K28) -> 10830
A30: TCO ИТ-решения | B30: =L28 -> 10830
A32: Примечание:
A33: * На этапе ОПЭ просьба указывать величину сервисных затрат, предварительно согласовав их с коллегами из сервисной функции
A34: ** Строки 8,9,25 указаны как "в том числе", входят в статьи "Консалтинг внешний" и "Затраты на сопровождение на этапе эксплуатации". Выделяются для контроля расходов на ИБ.

Sheet Дерево КПЭ (Проект 1)
A1: ДЕРЕВО КПЭ ПРОЕКТА U20000XXXX
A3: № | B3: Проекты | C3: Уровень 4 | D3: Тип эффекта | E3: Тип влияния на денежный поток | F3: Формула | G3: Тип показателя | H3: Уровень 3 - физические параметры | M3: Уровень 2 - операционные параметры | R3: Уровень 2 - экономический эффект | W3: Итого: | X3: Урвень 1 - показатели инвестиционной привлекательности | AA3: Уровень КПЭ | AB3: КПЭ | AC3: Ед. измерения | AD3: =I4 -> 2022 | AF3: =J4 -> 2023 | AH3: =K4 -> 2024 | AJ3: =L4 -> 2025
C4: Цели процесса | I4: 2022 | J4: 2023 | K4: 2024 | L4: 2025 | N4: 2022 | O4: 2023 | P4: 2024 | Q4: 2025 | S4: 2022 | T4: 2023 | U4: 2024 | V4: 2025 | AA4: Суммарный экономический эффект | AB4: Эконом. эффект от программы | AC4: Млн.р. \ год | AD4: ххх | AE4: =S22 -> 0 | AF4: ххх | AG4: =T22 -> 0 | AH4: ххх | AI4: =U22 -> 0 | AJ4: ххх | AK4: =V22 -> 0
A5: 1 | B5: U20000XXXX | C5: Внедрение инструмента по управлению ИТ активами | D5: Оптимизация затрат | E5: прямой | F5: ([текущий коэф. оборачиваемости] / [целевой коэф. оборачиваемости])*[среднегодовая стоимость склада, млн руб.]*[Стоимость обслуживания капитала, %/год] | G5: AS IS | H5: Поввышение коэффициента оборачиваемости | I5: 2.8 | J5: 2.8 | K5: 2.8 | L5: 2.8 | M5: Стоимость обслуживания капитала, тыс. руб. | N5: =I7*I8 -> 59200.39 | O5: =J7*J8 -> 59200.39 | P5: =K7*K8 -> 59200.39 | Q5: =L7*L8 -> 59200.39 | R5: Снижение стоимости обслуживания капитала за счет повышения коэф. оборачиваемости, тыс. руб. | S5: =N5-N6 -> 0 | T5: =O5-O6 -> 3946.6927 | U5: =P5-P6 -> 7400.0487 | V5: =Q5-Q6 -> 7400.0487 | W5: =SUM(S5:V6) -> 18746.79 | X5: ='Резюме (Проекта 1)'!A8 -> Ожидаемая дисконтированная стоимость проекта, NPV (тыс. руб.) | Y5: ='Резюме (Проекта 1)'!B8 -> 5660.571 | AA5: Операционные КПЭ (2 уровень) | AB5: =M5 -> Стоимость обслуживания капитала, тыс. руб. | AC5: млн руб. | AD5: ххх | AE5: =N6 -> 59200.39 | AF5: ххх | AG5: =O6 -> 55253.697 | AH5: ххх | AI5: =P6 -> 51800.341 | AJ5: ххх | AK5: =Q6 -> 51800.341
G6: TO BE | I6: 2.8 | J6: 3 | K6: 3.2 | L6: 3.2 | N6: =(I5/I6)*I7*I8 -> 59200.39 | O6: =(J5/J6)*J7*J8 -> 55253.697 | P6: =(K5/K6)*K7*K8 -> 51800.341 | Q6: =(L5/L6)*L7*L8 -> 51800.341 | X6: ='Резюме (Проекта 1)'!A9 -> Ожидаемый индекс доходности, PI | Y6: ='Резюме (Проекта 1)'!B9 -> 1.9086965 | AB6: =M9 -> Трудозатраты на инветаризацию, тыс. руб. | AC6: млн руб. | AD6: ххх | AE6: =N10 -> 2660 | AF6: ххх | AG6: =O10 -> 2280 | AH6: ххх | AI6: =P10 -> 2280 | AJ6: ххх | AK6: =Q10 -> 2280
A7: 1.1 | B7: Справочно: | F7: Среднегодовая стоимость склада, тыс. руб. | I7: 657782.11 | J7: 657782.11 | K7: 657782.11 | L7: 657782.11 | X7: ='Резюме (Проекта 1)'!A11 -> Приведенная стоимость инвестиций (PVI) | Y7: ='Резюме (Проекта 1)'!B11 -> 6229.3309 | AA7: Физические параметры (3 уровень) | AB7: =H5 -> Поввышение коэффициента оборачиваемости | AC7: коэф. оборачиваемости | AD7: ххх | AE7: =I6 -> 2.8 | AF7: ххх | AG7: =J6 -> 3 | AH7: ххх | AI7: =K6 -> 3.2 | AJ7: ххх | AK7: =L6 -> 3.2
A8: 1.2 | B8: Справочно: | F8: Стоимость обслуживание капитала, %/год | I8: 0.09 | J8: 0.09 | K8: 0.09 | L8: 0.09 | X8: ='Резюме (Проекта 1)'!A12 -> DDP, лет Период окупаемости инвестиций | Y8: ='Резюме (Проекта 1)'!DPP -> 3.7097677 | AB8: =H9 -> Снижение трудозатрат на инветаризацию, FTE | AC8: FTE | AD8: ххх | AE8: =I10 -> 1.4 | AF8: ххх | AG8: =J10 -> 1.2 | AH8: ххх | AI8: =K10 -> 1.2 | AJ8: ххх | AK8: =L10 -> 1.2
A9: 2 | B9: U20000XXXX | C9: Внедрение инструмента по управлению ИТ активами | D9: Оптимизация затрат | E9: прямой | F9: ([текущие трудозатраты на инветаризацию, FTE] - [целевые трудозатраты на инветаризацию, FTE]) * [стоимость FTE] | G9: AS IS | H9: Снижение трудозатрат на инветаризацию, FTE | I9: 1.5 | J9: 1.5 | K9: 1.5 | L9: 1.5 | M9: Трудозатраты на инветаризацию, тыс. руб. | N9: =I9*$I$11 -> 2850 | O9: =J9*$I$11 -> 2850 | P9: =K9*$I$11 -> 2850 | Q9: =L9*$I$11 -> 2850 | R9: Снижение трудозатрат на инвентаризацию, тыс. руб. | S9: =N9-N10 -> 190 | T9: =O9-O10 -> 570 | U9: =P9-P10 -> 570 | V9: =Q9-Q10 -> 570 | W9: =SUM(S9:V10) -> 1900 | AA9: Примечание:
G10: TO BE | I10: 1.4 | J10: 1.2 | K10: 1.2 | L10: 1.2 | N10: =I10*$I$11 -> 2660 | O10: =J10*$I$11 -> 2280 | P10: =K10*$I$11 -> 2280 | Q10: =L10*$I$11 -> 2280 | AA10: Факт | AB10: План
A11: 2.1 | B11: Справочно: | C11: Стоимость 1-го FTE, тыс. руб. | I11: 1900
C12: ИТОГО ЭФФЕКТ увеличение дохода: | S12: =SUMIF($D5:$D134,"Увеличение дохода",S5:S134) -> 0 | T12: =SUMIF($D5:$D134,"Увеличение дохода",T5:T134) -> 0 | U12: =SUMIF($D5:$D134,"Увеличение дохода",U5:U134) -> 0 | V12: =SUMIF($D5:$D134,"Увеличение дохода",V5:V134) -> 0 | W12: =SUM(S12:V12) -> 0
C13: ИТОГО ЭФФЕКТ оптимизации затрат: | S13: =SUMIF($D5:$D134,"Оптимизация затрат",S5:S134) -> 190 | T13: =SUMIF($D5:$D134,"Оптимизация затрат",T5:T134) -> 4516.6927 | U13: =SUMIF($D5:$D134,"Оптимизация затрат",U5:U134) -> 7970.0487 | V13: =SUMIF($D5:$D134,"Оптимизация затрат",V5:V134) -> 7970.0487 | W13: =SUM(S13:V13) -> 20646.79
C14: ИТОГО ЭФФЕКТ снижение риска: | S14: =SUMIF($D5:$D134,"Снижение риска",S5:S134) -> 0 | T14: =SUMIF($D5:$D134,"Снижение риска",T5:T134) -> 0 | U14: =SUMIF($D5:$D134,"Снижение риска",U5:U134) -> 0 | V14: =SUMIF($D5:$D134,"Снижение риска",V5:V134) -> 0 | W14: =SUM(S14:V14) -> 0
C16: ИТОГО ЭФФЕКТ: | S16: =SUM(S13:S14) -> 190 | T16: =SUM(T13:T14) -> 4516.6927 | U16: =SUM(U13:U14) -> 7970.0487 | V16: =SUM(V13:V14) -> 7970.0487 | W16: =SUM(S16:V16) -> 20646.79
B19: Примечание:
B20: 1. При заполнении таблицы "Дерево КПЭ" требуется на доплнительных вкладках/листах настоящей книги привести исходные данные, на основании которых указываются значения на 3-м и 2-м уровнях дерева.
B21: По возможности, приводимые значения на дереве КПЭ требуется указывать в виде ссылок на исходные данные.
B22: В случае использования экспертных оценок, будьте консервативны в своих определениях! Обратитесь к представителям Бизнеса для получения точных данных.
B23: 2. Период получения эффекта равен периоду полезного использования результатов проекта или периоду расчета показателей экономической эффективности

Sheet Резюме (Проекта 1)
A1: Наименование проекта | B1: …
A2: Номер проекта | B2: …
A3: Входит в состав программы | B3: …
A4: Тип проекта | B4: ИТ / ЦТ
A5: Руководитель проекта | B5: …
A6: Аналитик проекта | B6: …
A8: Ожидаемая дисконтированная стоимость проекта, NPV (тыс. руб.) | B8: =SUM(B36:F36) -> 5660.571 | D8: Комментарий: желтым цветом выделены строки, которые заполняются с листов "TCO" и "Дерево КПЭ" Применение «гибридного подхода» для дисконтирования денежного потока: до начала базового периода, т.е. закрытые периоды считаются историческими и для них применяется номинальная ставка дисконтирования (по состоянию на 2024г. – 18%). Для денежных потоков с начала базового года (текущего года) – применяется ставка дисконтирования (согласно макропараметрам = 14%).
A9: Ожидаемый индекс доходности, PI | B9: =1+B8/B11 -> 1.9086965
A10: Модицифированная внутренняя норма рентабельности MIRR, % | B10: =(SUMIF(B32:S32,">0",B37:S37)/SUMIF(B32:S32,"<0",B37:S37))^(1/MAX($B$17:$S$17))-1 -> 0.44754103
A11: Приведенная стоимость инвестиций (PVI) | B11: =SUM(B35:F35) -> 6229.3309
A12: DDP, лет Период окупаемости инвестиций | B12: =IF(B8<0,"не окупается",SUM(B41:F41)) -> 3.7097677
A14: Ставка реинвестирования | B14: 0.14
A15: Ставка дисконтирования | B15: 0.18 | C15: 0.18 | D15: 0.18 | E15: 0.14 | F15: 0.14
A16: год | B16: 2021 | C16: 2022 | D16: 2023 | E16: 2024 | F16: 2025 | G16: Минимальное отрицательное значение OCF (столбец)
A17: период | B17: 0 | C17: 1 | D17: 2 | E17: 3 | F17: 4
A18: TCO
A19: Капитальные затраты (CAPEX): | B19: ='TCO (Проект 1)'!C15 -> 0 | C19: ='TCO (Проект 1)'!D15 -> 1750 | D19: ='TCO (Проект 1)'!E15 -> 5150 | E19: ='TCO (Проект 1)'!F15 -> 0 | F19: ='TCO (Проект 1)'!G15 -> 0
A20: Операционные затраты (OPEX): | B20: ='TCO (Проект 1)'!C26 -> 1280 | C20: ='TCO (Проект 1)'!D26 -> 550 | D20: ='TCO (Проект 1)'!E26 -> 300 | E20: ='TCO (Проект 1)'!F26 -> 300 | F20: ='TCO (Проект 1)'!G26 -> 300
A21: Итого по проекту за период (тыс. руб.): | B21: ='TCO (Проект 1)'!C28 -> 1280 | C21: ='TCO (Проект 1)'!D28 -> 2300 | D21: ='TCO (Проект 1)'!E28 -> 5450 | E21: ='TCO (Проект 1)'!F28 -> 300 | F21: ='TCO (Проект 1)'!G28 -> 300
A22: TCO дисконтированный | B22: =B21*B30 -> 1178.3355 | C22: =C21*C30 -> 1794.3404 | D22: =D21*D30 -> 3603.2258 | E22: =E21*E30 -> 189.65062 | F22: =F21*F30 -> 166.3602
A24: Экономический эффект
A25: Увеличение дохода | C25: ='Дерево КПЭ (Проект 1)'!S12 -> 0 | D25: ='Дерево КПЭ (Проект 1)'!T12 -> 0 | E25: ='Дерево КПЭ (Проект 1)'!U12 -> 0 | F25: ='Дерево КПЭ (Проект 1)'!V12 -> 0
A26: Оптимизация затрат | C26: ='Дерево КПЭ (Проект 1)'!S13 -> 190 | D26: ='Дерево КПЭ (Проект 1)'!T13 -> 4516.6927 | E26: ='Дерево КПЭ (Проект 1)'!U13 -> 7970.0487 | F26: ='Дерево КПЭ (Проект 1)'!V13 -> 7970.0487
A27: Снижение риска: | C27: ='Дерево КПЭ (Проект 1)'!S14 -> 0 | D27: ='Дерево КПЭ (Проект 1)'!T14 -> 0 | E27: ='Дерево КПЭ (Проект 1)'!U14 -> 0 | F27: ='Дерево КПЭ (Проект 1)'!V14 -> 0
A28: Итого | B28: =SUM(B25:B27) -> 0 | C28: =SUM(C25:C27) -> 190 | D28: =SUM(D25:D27) -> 4516.6927 | E28: =SUM(E25:E27) -> 7970.0487 | F28: =SUM(F25:F27) -> 7970.0487
A30: Коэффициент дисконтирования | B30: =1/(1+B15)^(B17+1/2) -> 0.92057462 | C30: =1/(1+C15)^(C17+1/2) -> 0.78014798 | D30: =1/(1+D15)^(D17+1/2) -> 0.66114236 | E30: =1/(1+E15)^(E17+1/2) -> 0.63216875 | F30: =1/(1+F15)^(F17+1/2) -> 0.55453399
A32: Cash flow, млн. руб. | B32: =-B21+B28 -> -1280 | C32: =-C21+C28 -> -2110 | D32: =-D21+D28 -> -933.30734 | E32: =-E21+E28 -> 7670.0487 | F32: =-F21+F28 -> 7670.0487
A33: OCF | B33: =-B20+B28 -> -1280 | C33: =-C20+C28 -> -360 | D33: =-D20+D28 -> 4216.6927 | E33: =-E20+E28 -> 7670.0487 | F33: =-F20+F28 -> 7670.0487
A34: Накопленный OCF | B34: =B33 -> -1280 | C34: =B34+C33 -> -1640 | D34: =C34+D33 -> 2576.6927 | E34: =D34+E33 -> 10246.741 | F34: =E34+F33 -> 17916.79 | G34: =IF(MIN(B34:F34)<0,MATCH(MIN(B34:F34),B34:F34,0),0) -> 2
A35: PVI / EPVI | B35: =IF(MATCH(B34,$B$34:$F$34,0)<=$G$34,(B19+ABS(B33))*B30,B19*B30) -> 1178.3355 | C35: =IF(MATCH(C34,$B$34:$F$34,0)<=$G$34,(C19+ABS(C33))*C30,C19*C30) -> 1646.1122 | D35: =IF(MATCH(D34,$B$34:$F$34,0)<=$G$34,(D19+ABS(D33))*D30,D19*D30) -> 3404.8831 | E35: =IF(MATCH(E34,$B$34:$F$34,0)<=$G$34,(E19+ABS(E33))*E30,E19*E30) -> 0 | F35: =IF(MATCH(F34,$B$34:$F$34,0)<=$G$34,(F19+ABS(F33))*F30,F19*F30) -> 0
A36: DCF | B36: =B30*B32 -> -1178.3355 | C36: =C30*C32 -> -1646.1122 | D36: =D30*D32 -> -617.04901 | E36: =E30*E32 -> 4848.7651 | F36: =F30*F32 -> 4253.3027
A37: Справочно: для рассчёта MIRR | B37: =IF(B32>0,B32*(1+$B$14)^(MAX($B$17:$S$17)-B17),-B32/(1+B15)^(B17)) -> 1280 | C37: =IF(C32>0,C32*(1+$B$14)^(MAX($B$17:$S$17)-C17),-C32/(1+C15)^(C17)) -> 1788.1356 | D37: =IF(D32>0,D32*(1+$B$14)^(MAX($B$17:$S$17)-D17),-D32/(1+D15)^(D17)) -> 670.2868 | E37: =IF(E32>0,E32*(1+$B$14)^(MAX($B$17:$S$17)-E17),-E32/(1+E15)^(E17)) -> 8743.8556 | F37: =IF(F32>0,F32*(1+$B$14)^(MAX($B$17:$S$17)-F17),-F32/(1+F15)^(F17)) -> 7670.0487 | G37: =IF(G32>0,G32*(1+$B$14)^(MAX($B$17:$S$17)-G17),-G32/(1+G15)^(G17)) -> 0 | H37: =IF(H32>0,H32*(1+$B$14)^(MAX($B$17:$S$17)-H17),-H32/(1+H15)^(H17)) -> 0 | I37: =IF(I32>0,I32*(1+$B$14)^(MAX($B$17:$S$17)-I17),-I32/(1+I15)^(I17)) -> 0 | ... S37: =IF(S32>0,S32*(1+$B$14)^(MAX($B$17:$S$17)-S17),-S32/(1+S15)^(S17)) -> 0
A38: Накопленный CF | B38: =B32 -> -1280 | C38: =B38+C32 -> -3390 | D38: =C38+D32 -> -4323.3073 | E38: =D38+E32 -> 3346.7414 | F38: =E38+F32 -> 11016.79
A39: Простая окупаемость (PP), лет | B39: =IF(B38<0,1,B21/B28) -> 1 | C39: =IF(C38<0,1,IF(B39<1,0,ABS(B38)/(ABS(B38)+C38))) -> 1 | D39: =IF(D38<0,1,IF(C39<1,0,ABS(C38)/(ABS(C38)+D38))) -> 1 | E39: =IF(E38<0,1,IF(D39<1,0,ABS(D38)/(ABS(D38)+E38))) -> 0.563661 | F39: =IF(F38<0,1,IF(E39<1,0,ABS(E38)/(ABS(E38)+F38))) -> 0
A40: Накопленный DCF, млн. руб. | B40: =B36 -> -1178.3355 | C40: =C36+B40 -> -2824.4478 | D40: =D36+C40 -> -3441.4968 | E40: =E36+D40 -> 1407.2683 | F40: =F36+E40 -> 5660.571
A41: Дисконтированная окупаемость, лет | B41: =IF(B38<0,1,B21/B28) -> 1 | C41: =IF(C40<0,1,IF(B41<1,0,ABS(B40)/(ABS(B40)+C40))) -> 1 | D41: =IF(D40<0,1,IF(C41<1,0,ABS(C40)/(ABS(C40)+D40))) -> 1 | E41: =IF(E40<0,1,IF(D41<1,0,ABS(D40)/(ABS(D40)+E40))) -> 0.70976768 | F41: =IF(F40<0,1,IF(E41<1,0,ABS(E40)/(ABS(E40)+F40))) -> 0
A42: =IF(DPP="не окупается","Не окупается","DPP"&" "&IF(DPP=">10",">10",ROUND(DPP,2))&" (год)") -> DPP 3,71 (год)
A44: ФАКТОРНЫЙ АНАЛИЗ ЭКОНОМИЧЕСКОГО ЭФФЕКТА
A45: Наименование драйвера | B45: 2021 | C45: 2022 | D45: 2023 | E45: 2024 | F45: 2025 | G45: ИТОГО:
A46: ='Дерево КПЭ (Проект 1)'!R5 -> Снижение стоимости обслуживания капитала за счет повышения коэф. оборачиваемости, тыс. руб. | C46: ='Дерево КПЭ (Проект 1)'!S5*C30 -> 0 | D46: ='Дерево КПЭ (Проект 1)'!T5*D30 -> 2609.3257 | E46: ='Дерево КПЭ (Проект 1)'!U5*E30 -> 4678.0795 | F46: ='Дерево КПЭ (Проект 1)'!V5*F30 -> 4103.5785 | G46: =SUM(B46:F46) -> 11390.984
...

Sheet Факторный анализ
A1: При необходимости более глубокого анализа причин изменения показателей экономической эффективности программы, может быть произведен факторный анализ отклонений целевых операционных показателей. Данный анализ является дополнительной аналитикой, формирование которой оставляется на усмотрение конечным исполнителям. Результаты указанного анализа могут быть использованы для проведения управляющего комитета программы.
A4: Факторный анализ достижения КПЭ, млн руб.
A6: КПЭ | B6: 2019 | E6: 2020 | H6: 2021 | K6: 2022 | N6: ИТОГО
B7: План | C7: Факт | D7: Откл. | E7: План | F7: Факт | G7: Откл. | H7: План | I7: Факт | J7: Откл. | K7: План | L7: Факт | M7: Откл. | N7: План | O7: Факт | P7: Откл.
A8: Суммарный экономический эффект по программе | B8: =B9+B12 -> 39.3 | C8: =C9+C12 -> 40.8 | D8: =C8/B8-1 -> 0.038167939 | E8: =E9+E12 -> 49.9 | F8: =F9+F12 -> 51.5 | G8: =F8/E8-1 -> 0.032064128 | N8: =IFERROR(B8+E8+H8+K8,"") -> 89.2 | O8: =IFERROR(C8+F8+I8+L8,"") -> 92.3 | P8: =O8/N8-1 -> 0.034753363
A9: 1. Снижение лицензионных отчислений | B9: 25 | C9: 29.3 | D9: =C9/B9-1 -> 0.172 | E9: 31 | F9: 36.5 | G9: =F9/E9-1 -> 0.17741935 | N9: =IFERROR(B9+E9+H9+K9,"") -> 56 | O9: =IFERROR(C9+F9+I9+L9,"") -> 65.8 | P9: =O9/N9-1 -> 0.175
A10: 1.1 Кол-во приобретаемых лицензий | B10: 7 | E10: 0.2 | H10: xxx | K10: xxx | N10: =SUM(B10:L10) -> 7.2
A11: 1.2 Размер скидки на приобретение лицензионного обеспечения | B11: =-2.7 -> -2.7 | E11: 5.3 | H11: xxx | K11: xxx | N11: =SUM(B11:L11) -> 2.6
A12: 2. Снижение стоимости управления реализацией ЗнИ | B12: 14.3 | C12: 11.5 | D12: =C12/B12-1 -> -0.1958042 | E12: 18.9 | F12: 15 | G12: =F12/E12-1 -> -0.20634921 | N12: =IFERROR(B12+E12+H12+K12,"") -> 33.2 | O12: =IFERROR(C12+F12+I12+L12,"") -> 26.5 | P12: =O12/N12-1 -> -0.20180723
A13: 2.1 Кол-во ЗнИ | B13: =-5.4 -> -5.4 | E13: =-4.3 -> -4.3 | H13: xxx | K13: xxx | N13: =SUM(B13:L13) -> -9.7
A14: 2.2 Сокращение трудозатрат на обработку запросов на изменения | B14: 4.3 | E14: 3.8 | H14: xxx | K14: xxx | N14: =SUM(B14:L14) -> 8.1
A15: 2.3 Снижение трудозатрат на дублирующие ЗнИ | B15: =-1.7 -> -1.7 | E15: 4.4 | H15: xxx | K15: xxx | N15: =SUM(B15:L15) -> 2.7
A16: 3. Снижение стоимости заемного капитала | B16: 14 | C16: 15.1 | D16: =C16/B16-1 -> 0.078571429 | E16: 20.1 | F16: 16.8 | G16: =F16/E16-1 -> -0.1641791 | N16: =IFERROR(B16+E16+H16+K16,"") -> 34.1 | O16: =IFERROR(C16+F16+I16+L16,"") -> 31.9 | P16: =O16/N16-1 -> -0.064516129
A17: 3.1 Повышение оборачиваемости склада | B17: 0.6 | E17: 1.2 | H17: xxx | K17: xxx | N17: =SUM(B17:L17) -> 1.8
A18: 3.2 Среднегодовая стоимость складских запасов | B18: 0.5 | E18: 2.1 | H18: xxx | K18: xxx | N18: =SUM(B18:L18) -> 2.6
A20: Факторный анализ производится методом цепных подстановок
A22: Примечание:
A23: В общем виде факторный анализ для трехфакторной мультипликативной модели выглядит следующим образом:
A24: Плановое значение | B24: R0 = a0 * b0 * c0
A25: Фактическое значение | B25: R1 = a1 * b1 * c1
A27: Расчёты влияния факторов:
A28: 1. R(a) = ∆a * b0 * c0
A29: 2. R(b) = a1 * ∆b * c0
A30: 3. R(c) = a1 * b1 * ∆c
A32: Проверка
A33: R1-R0 = ∆R(a) + ∆R(b) + ∆R(c)
A35: Ключевое правило метода цепных подстановок: влияние изменения на результативный показатель количественного фактора подсчитывается при базовом значении качественного фактора.
A36: Так, если требуется определить степень влияния кол-ва проданной продукции и цены единицы товара на выручку подразделения, то прежде устанавливается влияние количественного показателя в виде объёма проданной продукции, а потом качественного показателя - цены товара
A38: Факторный анализ оказывает влияние на достижение физических показателей эффективности
